Workbook

Sheet Overview
A1: Ad Campaign Performance – Metrics Overview
A2: All values are live formulas on the Data sheet (936 ads with at least one click; the 207 zero-click, zero-spend ads are excluded, see Reconciliation).
A4: Metric | B4: Value | C4: Definition
A5: Ads | B5: =COUNTA(Data!A2:A937) -> 936 | C5: Number of ad rows
A6: Distinct fb campaigns | B6: =SUMPRODUCT(1/COUNTIF(Data!$C$2:$C$937,Data!$C$2:$C$937)) -> 543 | C6: Unique fb_campaign_id
A7: Impressions | B7: =SUM(Data!$G$2:$G$937) -> 212945947 | C7: Total ad views
A8: Clicks | B8: =SUM(Data!$H$2:$H$937) -> 38165 | C8: Total ad clicks
A9: Spent ($) | B9: =SUM(Data!$I$2:$I$937) -> 58705.23 | C9: Total cost
A10: Total Conversions | B10: =SUM(Data!$J$2:$J$937) -> 3052 | C10: Enquiries / leads recorded
A11: Approved Conversions | B11: =SUM(Data!$K$2:$K$937) -> 1003 | C11: Purchases confirmed
A12: CTR % | B12: =B8/B7 -> 0.00017922389 | C12: Clicks ÷ Impressions
A13: CPM ($) | B13: =B9/B7*1000 -> 0.27568137 | C13: Spend per 1,000 impressions
A14: CPC ($) | B14: =B9/B8 -> 1.5381955 | C14: Spend ÷ Clicks
A15: Conversion Rate (CR) | B15: =B10/B8 -> 0.079968558 | C15: Total conversions ÷ Clicks
A16: Approved Conv. Rate (ACR) | B16: =B11/B8 -> 0.026280624 | C16: Approved conversions ÷ Clicks
A17: Approval Rate (AR) | B17: =B11/B10 -> 0.32863696 | C17: Approved ÷ Total conversions
A18: Cost / Total Conv. ($) | B18: =B9/B10 -> 19.235003 | C18: Spend ÷ Total conversions
A19: Cost / Approved Conv. ($) | B19: =B9/B11 -> 58.529641 | C19: Spend ÷ Approved conversions (CPA)
A20: Avg spend per ad ($) | B20: =B9/B5 -> 62.719263 | C20: Spend ÷ Ads
A21: Ads with zero approved conv. | B21: =COUNTIF(Data!$K$2:$K$937,0) -> 423 | C21: Count of ads
A22: Spend on zero-approved ads ($) | B22: =SUMIFS(Data!$I$2:$I$937,Data!$K$2:$K$937,0) -> 14754.42 | C22: Budget with no approved result
A23: as % of total spend | B23: =B22/B9 -> 0.25133059 | C23: Share of budget
A25: Note: "Total Conversion" = enquiries/leads; "Approved Conversion" = purchases (per the standard reading of this dataset). Confirm with the data owner.

Sheet Campaign
A1: Performance by Campaign
A2: xyz_campaign_id
A4: Campaign | B4: Ads | C4: Impressions | D4: Clicks | E4: Spent ($) | F4: Total Conv. | G4: Approved Conv. | H4: CTR % | I4: CPM ($) | J4: CPC ($) | K4: Conv. Rate (CR) | L4: Approved Conv. Rate (ACR) | M4: Approval Rate (AR) | N4: Cost / Total Conv. ($) | O4: Cost / Approved Conv. ($) | P4: Spend Share | Q4: Approved Share | R4: Efficiency Index
A5: 916 | B5: =COUNTIFS(Data!$B$2:$B$937,$A5) -> 35 | C5: =SUMIFS(Data!$G$2:$G$937,Data!$B$2:$B$937,$A5) -> 448046 | D5: =SUMIFS(Data!$H$2:$H$937,Data!$B$2:$B$937,$A5) -> 113 | E5: =SUMIFS(Data!$I$2:$I$937,Data!$B$2:$B$937,$A5) -> 149.71 | F5: =SUMIFS(Data!$J$2:$J$937,Data!$B$2:$B$937,$A5) -> 39 | G5: =SUMIFS(Data!$K$2:$K$937,Data!$B$2:$B$937,$A5) -> 16 | H5: =IFERROR(D5/C5,0) -> 0.00025220625 | I5: =IFERROR(E5/C5*1000,0) -> 0.3341398 | J5: =IFERROR(E5/D5,0) -> 1.3248673 | K5: =IFERROR(F5/D5,0) -> 0.34513274 | L5: =IFERROR(G5/D5,0) -> 0.14159292 | M5: =IFERROR(G5/F5,0) -> 0.41025641 | N5: =IFERROR(E5/F5,0) -> 3.838718 | O5: =IFERROR(E5/G5,0) -> 9.356875 | P5: =IFERROR(E5/E$8,0) -> 0.0025501987 | Q5: =IFERROR(G5/G$8,0) -> 0.015952144 | R5: =IFERROR(Q5/P5,0) -> 6.2552552
A6: 936 | B6: =COUNTIFS(Data!$B$2:$B$937,$A6) -> 288 | C6: =SUMIFS(Data!$G$2:$G$937,Data!$B$2:$B$937,$A6) -> 7797942 | D6: =SUMIFS(Data!$H$2:$H$937,Data!$B$2:$B$937,$A6) -> 1984 | E6: =SUMIFS(Data!$I$2:$I$937,Data!$B$2:$B$937,$A6) -> 2893.37 | F6: =SUMIFS(Data!$J$2:$J$937,Data!$B$2:$B$937,$A6) -> 356 | G6: =SUMIFS(Data!$K$2:$K$937,Data!$B$2:$B$937,$A6) -> 118 | H6: =IFERROR(D6/C6,0) -> 0.0002544261 | I6: =IFERROR(E6/C6*1000,0) -> 0.37104277 | J6: =IFERROR(E6/D6,0) -> 1.4583518 | K6: =IFERROR(F6/D6,0) -> 0.17943548 | L6: =IFERROR(G6/D6,0) -> 0.059475806 | M6: =IFERROR(G6/F6,0) -> 0.33146067 | N6: =IFERROR(E6/F6,0) -> 8.1274438 | O6: =IFERROR(E6/G6,0) -> 24.520085 | P6: =IFERROR(E6/E$8,0) -> 0.049286409 | Q6: =IFERROR(G6/G$8,0) -> 0.11764706 | R6: =IFERROR(Q6/P6,0) -> 2.3870081
A7: 1178 | B7: =COUNTIFS(Data!$B$2:$B$937,$A7) -> 613 | C7: =SUMIFS(Data!$G$2:$G$937,Data!$B$2:$B$937,$A7) -> 204699959 | D7: =SUMIFS(Data!$H$2:$H$937,Data!$B$2:$B$937,$A7) -> 36068 | E7: =SUMIFS(Data!$I$2:$I$937,Data!$B$2:$B$937,$A7) -> 55662.15 | F7: =SUMIFS(Data!$J$2:$J$937,Data!$B$2:$B$937,$A7) -> 2657 | G7: =SUMIFS(Data!$K$2:$K$937,Data!$B$2:$B$937,$A7) -> 869 | H7: =IFERROR(D7/C7,0) -> 0.00017619935 | I7: =IFERROR(E7/C7*1000,0) -> 0.27192067 | J7: =IFERROR(E7/D7,0) -> 1.5432558 | K7: =IFERROR(F7/D7,0) -> 0.073666408 | L7: =IFERROR(G7/D7,0) -> 0.024093379 | M7: =IFERROR(G7/F7,0) -> 0.32706059 | N7: =IFERROR(E7/F7,0) -> 20.949247 | O7: =IFERROR(E7/G7,0) -> 64.053107 | P7: =IFERROR(E7/E$8,0) -> 0.94816339 | Q7: =IFERROR(G7/G$8,0) -> 0.8664008 | R7: =IFERROR(Q7/P7,0) -> 0.9137674
A8: Total | B8: =SUM(B5:B7) -> 936 | C8: =SUM(C5:C7) -> 212945947 | D8: =SUM(D5:D7) -> 38165 | E8: =SUM(E5:E7) -> 58705.23 | F8: =SUM(F5:F7) -> 3052 | G8: =SUM(G5:G7) -> 1003 | H8: =IFERROR(D8/C8,0) -> 0.00017922389 | I8: =IFERROR(E8/C8*1000,0) -> 0.27568137 | J8: =IFERROR(E8/D8,0) -> 1.5381955 | K8: =IFERROR(F8/D8,0) -> 0.079968558 | L8: =IFERROR(G8/D8,0) -> 0.026280624 | M8: =IFERROR(G8/F8,0) -> 0.32863696 | N8: =IFERROR(E8/F8,0) -> 19.235003 | O8: =IFERROR(E8/G8,0) -> 58.529641 | P8: =IFERROR(E8/E$8,0) -> 1 | Q8: =IFERROR(G8/G$8,0) -> 1 | R8: =IFERROR(Q8/P8,0) -> 1
A10: Efficiency Index = Approved Share ÷ Spend Share. Above 1.0 = the segment returns more approved conversions than its share of budget.

Sheet Age
A1: Performance by Age Group
A4: Age | B4: Ads | C4: Impressions | D4: Clicks | E4: Spent ($) | F4: Total Conv. | G4: Approved Conv. | H4: CTR % | I4: CPM ($) | J4: CPC ($) | K4: Conv. Rate (CR) | L4: Approved Conv. Rate (ACR) | M4: Approval Rate (AR) | N4: Cost / Total Conv. ($) | O4: Cost / Approved Conv. ($) | P4: Spend Share | Q4: Approved Share | R4: Efficiency Index
A5: 30-34 | B5: =COUNTIFS(Data!$D$2:$D$937,$A5) -> 307 | C5: =SUMIFS(Data!$G$2:$G$937,Data!$D$2:$D$937,$A5) -> 67674431 | D5: =SUMIFS(Data!$H$2:$H$937,Data!$D$2:$D$937,$A5) -> 9483 | E5: =SUMIFS(Data!$I$2:$I$937,Data!$D$2:$D$937,$A5) -> 15252.4 | F5: =SUMIFS(Data!$J$2:$J$937,Data!$D$2:$D$937,$A5) -> 1307 | G5: =SUMIFS(Data!$K$2:$K$937,Data!$D$2:$D$937,$A5) -> 443 | H5: =IFERROR(D5/C5,0) -> 0.00014012678 | I5: =IFERROR(E5/C5*1000,0) -> 0.22537907 | J5: =IFERROR(E5/D5,0) -> 1.608394 | K5: =IFERROR(F5/D5,0) -> 0.13782558 | L5: =IFERROR(G5/D5,0) -> 0.046715175 | M5: =IFERROR(G5/F5,0) -> 0.33894415 | N5: =IFERROR(E5/F5,0) -> 11.669778 | O5: =IFERROR(E5/G5,0) -> 34.429797 | P5: =IFERROR(E5/E$9,0) -> 0.25981331 | Q5: =IFERROR(G5/G$9,0) -> 0.44167498 | R5: =IFERROR(Q5/P5,0) -> 1.6999706
A6: 35-39 | B6: =COUNTIFS(Data!$D$2:$D$937,$A6) -> 211 | C6: =SUMIFS(Data!$G$2:$G$937,Data!$D$2:$D$937,$A6) -> 42021238 | D6: =SUMIFS(Data!$H$2:$H$937,Data!$D$2:$D$937,$A6) -> 7094 | E6: =SUMIFS(Data!$I$2:$I$937,Data!$D$2:$D$937,$A6) -> 11112.43 | F6: =SUMIFS(Data!$J$2:$J$937,Data!$D$2:$D$937,$A6) -> 591 | G6: =SUMIFS(Data!$K$2:$K$937,Data!$D$2:$D$937,$A6) -> 199 | H6: =IFERROR(D6/C6,0) -> 0.0001688194 | I6: =IFERROR(E6/C6*1000,0) -> 0.26444794 | J6: =IFERROR(E6/D6,0) -> 1.5664547 | K6: =IFERROR(F6/D6,0) -> 0.083309839 | L6: =IFERROR(G6/D6,0) -> 0.028051875 | M6: =IFERROR(G6/F6,0) -> 0.33671743 | N6: =IFERROR(E6/F6,0) -> 18.802758 | O6: =IFERROR(E6/G6,0) -> 55.841357 | P6: =IFERROR(E6/E$9,0) -> 0.18929199 | Q6: =IFERROR(G6/G$9,0) -> 0.19840479 | R6: =IFERROR(Q6/P6,0) -> 1.0481415
A7: 40-44 | B7: =COUNTIFS(Data!$D$2:$D$937,$A7) -> 187 | C7: =SUMIFS(Data!$G$2:$G$937,Data!$D$2:$D$937,$A7) -> 39551158 | D7: =SUMIFS(Data!$H$2:$H$937,Data!$D$2:$D$937,$A7) -> 7736 | E7: =SUMIFS(Data!$I$2:$I$937,Data!$D$2:$D$937,$A7) -> 11589.73 | F7: =SUMIFS(Data!$J$2:$J$937,Data!$D$2:$D$937,$A7) -> 499 | G7: =SUMIFS(Data!$K$2:$K$937,Data!$D$2:$D$937,$A7) -> 162 | H7: =IFERROR(D7/C7,0) -> 0.00019559478 | I7: =IFERROR(E7/C7*1000,0) -> 0.29303137 | J7: =IFERROR(E7/D7,0) -> 1.4981554 | K7: =IFERROR(F7/D7,0) -> 0.064503619 | L7: =IFERROR(G7/D7,0) -> 0.020941055 | M7: =IFERROR(G7/F7,0) -> 0.3246493 | N7: =IFERROR(E7/F7,0) -> 23.225912 | O7: =IFERROR(E7/G7,0) -> 71.541543 | P7: =IFERROR(E7/E$9,0) -> 0.19742244 | Q7: =IFERROR(G7/G$9,0) -> 0.16151545 | R7: =IFERROR(Q7/P7,0) -> 0.81812103
A8: 45-49 | B8: =COUNTIFS(Data!$D$2:$D$937,$A8) -> 231 | C8: =SUMIFS(Data!$G$2:$G$937,Data!$D$2:$D$937,$A8) -> 63699120 | D8: =SUMIFS(Data!$H$2:$H$937,Data!$D$2:$D$937,$A8) -> 13852 | E8: =SUMIFS(Data!$I$2:$I$937,Data!$D$2:$D$937,$A8) -> 20750.67 | F8: =SUMIFS(Data!$J$2:$J$937,Data!$D$2:$D$937,$A8) -> 655 | G8: =SUMIFS(Data!$K$2:$K$937,Data!$D$2:$D$937,$A8) -> 199 | H8: =IFERROR(D8/C8,0) -> 0.00021745983 | I8: =IFERROR(E8/C8*1000,0) -> 0.3257607 | J8: =IFERROR(E8/D8,0) -> 1.498027 | K8: =IFERROR(F8/D8,0) -> 0.047285591 | L8: =IFERROR(G8/D8,0) -> 0.014366157 | M8: =IFERROR(G8/F8,0) -> 0.30381679 | N8: =IFERROR(E8/F8,0) -> 31.680412 | O8: =IFERROR(E8/G8,0) -> 104.27472 | P8: =IFERROR(E8/E$9,0) -> 0.35347225 | Q8: =IFERROR(G8/G$9,0) -> 0.19840479 | R8: =IFERROR(Q8/P8,0) -> 0.56130229
A9: Total | B9: =SUM(B5:B8) -> 936 | C9: =SUM(C5:C8) -> 212945947 | D9: =SUM(D5:D8) -> 38165 | E9: =SUM(E5:E8) -> 58705.23 | F9: =SUM(F5:F8) -> 3052 | G9: =SUM(G5:G8) -> 1003 | H9: =IFERROR(D9/C9,0) -> 0.00017922389 | I9: =IFERROR(E9/C9*1000,0) -> 0.27568137 | J9: =IFERROR(E9/D9,0) -> 1.5381955 | K9: =IFERROR(F9/D9,0) -> 0.079968558 | L9: =IFERROR(G9/D9,0) -> 0.026280624 | M9: =IFERROR(G9/F9,0) -> 0.32863696 | N9: =IFERROR(E9/F9,0) -> 19.235003 | O9: =IFERROR(E9/G9,0) -> 58.529641 | P9: =IFERROR(E9/E$9,0) -> 1 | Q9: =IFERROR(G9/G$9,0) -> 1 | R9: =IFERROR(Q9/P9,0) -> 1
A11: Efficiency Index = Approved Share ÷ Spend Share. Above 1.0 = the segment returns more approved conversions than its share of budget.

Sheet Gender
A1: Performance by Gender
A4: Gender | B4: Ads | C4: Impressions | D4: Clicks | E4: Spent ($) | F4: Total Conv. | G4: Approved Conv. | H4: CTR % | I4: CPM ($) | J4: CPC ($) | K4: Conv. Rate (CR) | L4: Approved Conv. Rate (ACR) | M4: Approval Rate (AR) | N4: Cost / Total Conv. ($) | O4: Cost / Approved Conv. ($) | P4: Spend Share | Q4: Approved Share | R4: Efficiency Index
A5: F | B5: =COUNTIFS(Data!$E$2:$E$937,$A5) -> 463 | C5: =SUMIFS(Data!$G$2:$G$937,Data!$E$2:$E$937,$A5) -> 114707607 | D5: =SUMIFS(Data!$H$2:$H$937,Data!$E$2:$E$937,$A5) -> 23878 | E5: =SUMIFS(Data!$I$2:$I$937,Data!$E$2:$E$937,$A5) -> 34502.62 | F5: =SUMIFS(Data!$J$2:$J$937,Data!$E$2:$E$937,$A5) -> 1557 | G5: =SUMIFS(Data!$K$2:$K$937,Data!$E$2:$E$937,$A5) -> 467 | H5: =IFERROR(D5/C5,0) -> 0.00020816405 | I5: =IFERROR(E5/C5*1000,0) -> 0.30078755 | J5: =IFERROR(E5/D5,0) -> 1.4449543 | K5: =IFERROR(F5/D5,0) -> 0.065206466 | L5: =IFERROR(G5/D5,0) -> 0.019557752 | M5: =IFERROR(G5/F5,0) -> 0.29993577 | N5: =IFERROR(E5/F5,0) -> 22.159679 | O5: =IFERROR(E5/G5,0) -> 73.881413 | P5: =IFERROR(E5/E$7,0) -> 0.58772651 | Q5: =IFERROR(G5/G$7,0) -> 0.46560319 | R5: =IFERROR(Q5/P5,0) -> 0.79221063
A6: M | B6: =COUNTIFS(Data!$E$2:$E$937,$A6) -> 473 | C6: =SUMIFS(Data!$G$2:$G$937,Data!$E$2:$E$937,$A6) -> 98238340 | D6: =SUMIFS(Data!$H$2:$H$937,Data!$E$2:$E$937,$A6) -> 14287 | E6: =SUMIFS(Data!$I$2:$I$937,Data!$E$2:$E$937,$A6) -> 24202.61 | F6: =SUMIFS(Data!$J$2:$J$937,Data!$E$2:$E$937,$A6) -> 1495 | G6: =SUMIFS(Data!$K$2:$K$937,Data!$E$2:$E$937,$A6) -> 536 | H6: =IFERROR(D6/C6,0) -> 0.00014543202 | I6: =IFERROR(E6/C6*1000,0) -> 0.24636624 | J6: =IFERROR(E6/D6,0) -> 1.6940302 | K6: =IFERROR(F6/D6,0) -> 0.10464058 | L6: =IFERROR(G6/D6,0) -> 0.037516624 | M6: =IFERROR(G6/F6,0) -> 0.35852843 | N6: =IFERROR(E6/F6,0) -> 16.189037 | O6: =IFERROR(E6/G6,0) -> 45.154123 | P6: =IFERROR(E6/E$7,0) -> 0.41227349 | Q6: =IFERROR(G6/G$7,0) -> 0.53439681 | R6: =IFERROR(Q6/P6,0) -> 1.2962192
A7: Total | B7: =SUM(B5:B6) -> 936 | C7: =SUM(C5:C6) -> 212945947 | D7: =SUM(D5:D6) -> 38165 | E7: =SUM(E5:E6) -> 58705.23 | F7: =SUM(F5:F6) -> 3052 | G7: =SUM(G5:G6) -> 1003 | H7: =IFERROR(D7/C7,0) -> 0.00017922389 | I7: =IFERROR(E7/C7*1000,0) -> 0.27568137 | J7: =IFERROR(E7/D7,0) -> 1.5381955 | K7: =IFERROR(F7/D7,0) -> 0.079968558 | L7: =IFERROR(G7/D7,0) -> 0.026280624 | M7: =IFERROR(G7/F7,0) -> 0.32863696 | N7: =IFERROR(E7/F7,0) -> 19.235003 | O7: =IFERROR(E7/G7,0) -> 58.529641 | P7: =IFERROR(E7/E$7,0) -> 1 | Q7: =IFERROR(G7/G$7,0) -> 1 | R7: =IFERROR(Q7/P7,0) -> 1
A9: Efficiency Index = Approved Share ÷ Spend Share. Above 1.0 = the segment returns more approved conversions than its share of budget.

Sheet Age x Gender
A1: Performance by Age x Gender
A4: Age | B4: Gender | C4: Ads | D4: Impressions | E4: Clicks | F4: Spent ($) | G4: Total Conv. | H4: Approved Conv. | I4: CTR % | J4: CPM ($) | K4: CPC ($) | L4: Conv. Rate (CR) | M4: Approved Conv. Rate (ACR) | N4: Approval Rate (AR) | O4: Cost / Total Conv. ($) | P4: Cost / Approved Conv. ($) | Q4: Spend Share | R4: Approved Share | S4: Efficiency Index
A5: 30-34 | B5: F | C5: =COUNTIFS(Data!$D$2:$D$937,$A5,Data!$E$2:$E$937,$B5) -> 149 | D5: =SUMIFS(Data!$G$2:$G$937,Data!$D$2:$D$937,$A5,Data!$E$2:$E$937,$B5) -> 31463353 | E5: =SUMIFS(Data!$H$2:$H$937,Data!$D$2:$D$937,$A5,Data!$E$2:$E$937,$B5) -> 5099 | F5: =SUMIFS(Data!$I$2:$I$937,Data!$D$2:$D$937,$A5,Data!$E$2:$E$937,$B5) -> 7611.48 | G5: =SUMIFS(Data!$J$2:$J$937,Data!$D$2:$D$937,$A5,Data!$E$2:$E$937,$B5) -> 570 | H5: =SUMIFS(Data!$K$2:$K$937,Data!$D$2:$D$937,$A5,Data!$E$2:$E$937,$B5) -> 180 | I5: =IFERROR(E5/D5,0) -> 0.00016206156 | J5: =IFERROR(F5/D5*1000,0) -> 0.24191573 | K5: =IFERROR(F5/E5,0) -> 1.4927398 | L5: =IFERROR(G5/E5,0) -> 0.11178662 | M5: =IFERROR(H5/E5,0) -> 0.035301039 | N5: =IFERROR(H5/G5,0) -> 0.31578947 | O5: =IFERROR(F5/G5,0) -> 13.353474 | P5: =IFERROR(F5/H5,0) -> 42.286 | Q5: =IFERROR(F5/F$13,0) -> 0.12965591 | R5: =IFERROR(H5/H$13,0) -> 0.17946162 | S5: =IFERROR(R5/Q5,0) -> 1.3841376
A6: 30-34 | B6: M | C6: =COUNTIFS(Data!$D$2:$D$937,$A6,Data!$E$2:$E$937,$B6) -> 158 | D6: =SUMIFS(Data!$G$2:$G$937,Data!$D$2:$D$937,$A6,Data!$E$2:$E$937,$B6) -> 36211078 | E6: =SUMIFS(Data!$H$2:$H$937,Data!$D$2:$D$937,$A6,Data!$E$2:$E$937,$B6) -> 4384 | F6: =SUMIFS(Data!$I$2:$I$937,Data!$D$2:$D$937,$A6,Data!$E$2:$E$937,$B6) -> 7640.92 | G6: =SUMIFS(Data!$J$2:$J$937,Data!$D$2:$D$937,$A6,Data!$E$2:$E$937,$B6) -> 737 | H6: =SUMIFS(Data!$K$2:$K$937,Data!$D$2:$D$937,$A6,Data!$E$2:$E$937,$B6) -> 263 | I6: =IFERROR(E6/D6,0) -> 0.00012106792 | J6: =IFERROR(F6/D6*1000,0) -> 0.21101056 | K6: =IFERROR(F6/E6,0) -> 1.7429106 | L6: =IFERROR(G6/E6,0) -> 0.16811131 | M6: =IFERROR(H6/E6,0) -> 0.059990876 | N6: =IFERROR(H6/G6,0) -> 0.3568521 | O6: =IFERROR(F6/G6,0) -> 10.367598 | P6: =IFERROR(F6/H6,0) -> 29.052928 | Q6: =IFERROR(F6/F$13,0) -> 0.1301574 | R6: =IFERROR(H6/H$13,0) -> 0.26221336 | S6: =IFERROR(R6/Q6,0) -> 2.0145867
A7: 35-39 | B7: F | C7: =COUNTIFS(Data!$D$2:$D$937,$A7,Data!$E$2:$E$937,$B7) -> 93 | D7: =SUMIFS(Data!$G$2:$G$937,Data!$D$2:$D$937,$A7,Data!$E$2:$E$937,$B7) -> 21420120 | E7: =SUMIFS(Data!$H$2:$H$937,Data!$D$2:$D$937,$A7,Data!$E$2:$E$937,$B7) -> 4161 | F7: =SUMIFS(Data!$I$2:$I$937,Data!$D$2:$D$937,$A7,Data!$E$2:$E$937,$B7) -> 6061.35 | G7: =SUMIFS(Data!$J$2:$J$937,Data!$D$2:$D$937,$A7,Data!$E$2:$E$937,$B7) -> 290 | H7: =SUMIFS(Data!$K$2:$K$937,Data!$D$2:$D$937,$A7,Data!$E$2:$E$937,$B7) -> 90 | I7: =IFERROR(E7/D7,0) -> 0.00019425661 | J7: =IFERROR(F7/D7*1000,0) -> 0.2829746 | K7: =IFERROR(F7/E7,0) -> 1.4567051 | L7: =IFERROR(G7/E7,0) -> 0.069694785 | M7: =IFERROR(H7/E7,0) -> 0.021629416 | N7: =IFERROR(H7/G7,0) -> 0.31034483 | O7: =IFERROR(F7/G7,0) -> 20.901207 | P7: =IFERROR(F7/H7,0) -> 67.348333 | Q7: =IFERROR(F7/F$13,0) -> 0.1032506 | R7: =IFERROR(H7/H$13,0) -> 0.089730808 | S7: =IFERROR(R7/Q7,0) -> 0.86905849
A8: 35-39 | B8: M | C8: =COUNTIFS(Data!$D$2:$D$937,$A8,Data!$E$2:$E$937,$B8) -> 118 | D8: =SUMIFS(Data!$G$2:$G$937,Data!$D$2:$D$937,$A8,Data!$E$2:$E$937,$B8) -> 20601118 | E8: =SUMIFS(Data!$H$2:$H$937,Data!$D$2:$D$937,$A8,Data!$E$2:$E$937,$B8) -> 2933 | F8: =SUMIFS(Data!$I$2:$I$937,Data!$D$2:$D$937,$A8,Data!$E$2:$E$937,$B8) -> 5051.08 | G8: =SUMIFS(Data!$J$2:$J$937,Data!$D$2:$D$937,$A8,Data!$E$2:$E$937,$B8) -> 301 | H8: =SUMIFS(Data!$K$2:$K$937,Data!$D$2:$D$937,$A8,Data!$E$2:$E$937,$B8) -> 109 | I8: =IFERROR(E8/D8,0) -> 0.00014237091 | J8: =IFERROR(F8/D8*1000,0) -> 0.24518475 | K8: =IFERROR(F8/E8,0) -> 1.7221548 | L8: =IFERROR(G8/E8,0) -> 0.1026253 | M8: =IFERROR(H8/E8,0) -> 0.037163314 | N8: =IFERROR(H8/G8,0) -> 0.36212625 | O8: =IFERROR(F8/G8,0) -> 16.780997 | P8: =IFERROR(F8/H8,0) -> 46.340184 | Q8: =IFERROR(F8/F$13,0) -> 0.086041397 | R8: =IFERROR(H8/H$13,0) -> 0.10867398 | S8: =IFERROR(R8/Q8,0) -> 1.2630429
A9: 40-44 | B9: F | C9: =COUNTIFS(Data!$D$2:$D$937,$A9,Data!$E$2:$E$937,$B9) -> 95 | D9: =SUMIFS(Data!$G$2:$G$937,Data!$D$2:$D$937,$A9,Data!$E$2:$E$937,$B9) -> 23386170 | E9: =SUMIFS(Data!$H$2:$H$937,Data!$D$2:$D$937,$A9,Data!$E$2:$E$937,$B9) -> 5177 | F9: =SUMIFS(Data!$I$2:$I$937,Data!$D$2:$D$937,$A9,Data!$E$2:$E$937,$B9) -> 7396.58 | G9: =SUMIFS(Data!$J$2:$J$937,Data!$D$2:$D$937,$A9,Data!$E$2:$E$937,$B9) -> 310 | H9: =SUMIFS(Data!$K$2:$K$937,Data!$D$2:$D$937,$A9,Data!$E$2:$E$937,$B9) -> 89 | I9: =IFERROR(E9/D9,0) -> 0.00022137015 | J9: =IFERROR(F9/D9*1000,0) -> 0.31628009 | K9: =IFERROR(F9/E9,0) -> 1.4287386 | L9: =IFERROR(G9/E9,0) -> 0.05988024 | M9: =IFERROR(H9/E9,0) -> 0.017191424 | N9: =IFERROR(H9/G9,0) -> 0.28709677 | O9: =IFERROR(F9/G9,0) -> 23.859935 | P9: =IFERROR(F9/H9,0) -> 83.10764 | Q9: =IFERROR(F9/F$13,0) -> 0.12599525 | R9: =IFERROR(H9/H$13,0) -> 0.088733799 | S9: =IFERROR(R9/Q9,0) -> 0.70426306
A10: 40-44 | B10: M | C10: =COUNTIFS(Data!$D$2:$D$937,$A10,Data!$E$2:$E$937,$B10) -> 92 | D10: =SUMIFS(Data!$G$2:$G$937,Data!$D$2:$D$937,$A10,Data!$E$2:$E$937,$B10) -> 16164988 | E10: =SUMIFS(Data!$H$2:$H$937,Data!$D$2:$D$937,$A10,Data!$E$2:$E$937,$B10) -> 2559 | F10: =SUMIFS(Data!$I$2:$I$937,Data!$D$2:$D$937,$A10,Data!$E$2:$E$937,$B10) -> 4193.15 | G10: =SUMIFS(Data!$J$2:$J$937,Data!$D$2:$D$937,$A10,Data!$E$2:$E$937,$B10) -> 189 | H10: =SUMIFS(Data!$K$2:$K$937,Data!$D$2:$D$937,$A10,Data!$E$2:$E$937,$B10) -> 73 | I10: =IFERROR(E10/D10,0) -> 0.0001583051 | J10: =IFERROR(F10/D10*1000,0) -> 0.25939704 | K10: =IFERROR(F10/E10,0) -> 1.6385893 | L10: =IFERROR(G10/E10,0) -> 0.073856975 | M10: =IFERROR(H10/E10,0) -> 0.028526768 | N10: =IFERROR(H10/G10,0) -> 0.38624339 | O10: =IFERROR(F10/G10,0) -> 22.185979 | P10: =IFERROR(F10/H10,0) -> 57.440411 | Q10: =IFERROR(F10/F$13,0) -> 0.071427197 | R10: =IFERROR(H10/H$13,0) -> 0.072781655 | S10: =IFERROR(R10/Q10,0) -> 1.0189628
A11: 45-49 | B11: F | C11: =COUNTIFS(Data!$D$2:$D$937,$A11,Data!$E$2:$E$937,$B11) -> 126 | D11: =SUMIFS(Data!$G$2:$G$937,Data!$D$2:$D$937,$A11,Data!$E$2:$E$937,$B11) -> 38437964 | E11: =SUMIFS(Data!$H$2:$H$937,Data!$D$2:$D$937,$A11,Data!$E$2:$E$937,$B11) -> 9441 | F11: =SUMIFS(Data!$I$2:$I$937,Data!$D$2:$D$937,$A11,Data!$E$2:$E$937,$B11) -> 13433.21 | G11: =SUMIFS(Data!$J$2:$J$937,Data!$D$2:$D$937,$A11,Data!$E$2:$E$937,$B11) -> 387 | H11: =SUMIFS(Data!$K$2:$K$937,Data!$D$2:$D$937,$A11,Data!$E$2:$E$937,$B11) -> 108 | I11: =IFERROR(E11/D11,0) -> 0.00024561655 | J11: =IFERROR(F11/D11*1000,0) -> 0.34947767 | K11: =IFERROR(F11/E11,0) -> 1.4228588 | L11: =IFERROR(G11/E11,0) -> 0.04099142 | M11: =IFERROR(H11/E11,0) -> 0.011439466 | N11: =IFERROR(H11/G11,0) -> 0.27906977 | O11: =IFERROR(F11/G11,0) -> 34.711137 | P11: =IFERROR(F11/H11,0) -> 124.38157 | Q11: =IFERROR(F11/F$13,0) -> 0.22882476 | R11: =IFERROR(H11/H$13,0) -> 0.10767697 | S11: =IFERROR(R11/Q11,0) -> 0.47056521
A12: 45-49 | B12: M | C12: =COUNTIFS(Data!$D$2:$D$937,$A12,Data!$E$2:$E$937,$B12) -> 105 | D12: =SUMIFS(Data!$G$2:$G$937,Data!$D$2:$D$937,$A12,Data!$E$2:$E$937,$B12) -> 25261156 | E12: =SUMIFS(Data!$H$2:$H$937,Data!$D$2:$D$937,$A12,Data!$E$2:$E$937,$B12) -> 4411 | F12: =SUMIFS(Data!$I$2:$I$937,Data!$D$2:$D$937,$A12,Data!$E$2:$E$937,$B12) -> 7317.46 | G12: =SUMIFS(Data!$J$2:$J$937,Data!$D$2:$D$937,$A12,Data!$E$2:$E$937,$B12) -> 268 | H12: =SUMIFS(Data!$K$2:$K$937,Data!$D$2:$D$937,$A12,Data!$E$2:$E$937,$B12) -> 91 | I12: =IFERROR(E12/D12,0) -> 0.00017461592 | J12: =IFERROR(F12/D12*1000,0) -> 0.28967241 | K12: =IFERROR(F12/E12,0) -> 1.6589118 | L12: =IFERROR(G12/E12,0) -> 0.060757198 | M12: =IFERROR(H12/E12,0) -> 0.020630243 | N12: =IFERROR(H12/G12,0) -> 0.33955224 | O12: =IFERROR(F12/G12,0) -> 27.303955 | P12: =IFERROR(F12/H12,0) -> 80.411648 | Q12: =IFERROR(F12/F$13,0) -> 0.1246475 | R12: =IFERROR(H12/H$13,0) -> 0.090727817 | S12: =IFERROR(R12/Q12,0) -> 0.72787515
A13: Total | C13: =SUM(C5:C12) -> 936 | D13: =SUM(D5:D12) -> 212945947 | E13: =SUM(E5:E12) -> 38165 | F13: =SUM(F5:F12) -> 58705.23 | G13: =SUM(G5:G12) -> 3052 | H13: =SUM(H5:H12) -> 1003 | I13: =IFERROR(E13/D13,0) -> 0.00017922389 | J13: =IFERROR(F13/D13*1000,0) -> 0.27568137 | K13: =IFERROR(F13/E13,0) -> 1.5381955 | L13: =IFERROR(G13/E13,0) -> 0.079968558 | M13: =IFERROR(H13/E13,0) -> 0.026280624 | N13: =IFERROR(H13/G13,0) -> 0.32863696 | O13: =IFERROR(F13/G13,0) -> 19.235003 | P13: =IFERROR(F13/H13,0) -> 58.529641 | Q13: =IFERROR(F13/F$13,0) -> 1 | R13: =IFERROR(H13/H$13,0) -> 1 | S13: =IFERROR(R13/Q13,0) -> 1
A15: Efficiency Index = Approved Share ÷ Spend Share. Above 1.0 = the segment returns more approved conversions than its share of budget.

Sheet Campaign x Gender
A1: Performance by Campaign x Gender
A4: Campaign | B4: Gender | C4: Ads | D4: Impressions | E4: Clicks | F4: Spent ($) | G4: Total Conv. | H4: Approved Conv. | I4: CTR % | J4: CPM ($) | K4: CPC ($) | L4: Conv. Rate (CR) | M4: Approved Conv. Rate (ACR) | N4: Approval Rate (AR) | O4: Cost / Total Conv. ($) | P4: Cost / Approved Conv. ($) | Q4: Spend Share | R4: Approved Share | S4: Efficiency Index
A5: 916 | B5: F | C5: =COUNTIFS(Data!$B$2:$B$937,$A5,Data!$E$2:$E$937,$B5) -> 13 | D5: =SUMIFS(Data!$G$2:$G$937,Data!$B$2:$B$937,$A5,Data!$E$2:$E$937,$B5) -> 188843 | E5: =SUMIFS(Data!$H$2:$H$937,Data!$B$2:$B$937,$A5,Data!$E$2:$E$937,$B5) -> 52 | F5: =SUMIFS(Data!$I$2:$I$937,Data!$B$2:$B$937,$A5,Data!$E$2:$E$937,$B5) -> 69.85 | G5: =SUMIFS(Data!$J$2:$J$937,Data!$B$2:$B$937,$A5,Data!$E$2:$E$937,$B5) -> 14 | H5: =SUMIFS(Data!$K$2:$K$937,Data!$B$2:$B$937,$A5,Data!$E$2:$E$937,$B5) -> 6 | I5: =IFERROR(E5/D5,0) -> 0.00027536101 | J5: =IFERROR(F5/D5*1000,0) -> 0.36988398 | K5: =IFERROR(F5/E5,0) -> 1.3432692 | L5: =IFERROR(G5/E5,0) -> 0.26923077 | M5: =IFERROR(H5/E5,0) -> 0.11538462 | N5: =IFERROR(H5/G5,0) -> 0.42857143 | O5: =IFERROR(F5/G5,0) -> 4.9892857 | P5: =IFERROR(F5/H5,0) -> 11.641667 | Q5: =IFERROR(F5/F$11,0) -> 0.0011898429 | R5: =IFERROR(H5/H$11,0) -> 0.0059820538 | S5: =IFERROR(R5/Q5,0) -> 5.0275998
A6: 916 | B6: M | C6: =COUNTIFS(Data!$B$2:$B$937,$A6,Data!$E$2:$E$937,$B6) -> 22 | D6: =SUMIFS(Data!$G$2:$G$937,Data!$B$2:$B$937,$A6,Data!$E$2:$E$937,$B6) -> 259203 | E6: =SUMIFS(Data!$H$2:$H$937,Data!$B$2:$B$937,$A6,Data!$E$2:$E$937,$B6) -> 61 | F6: =SUMIFS(Data!$I$2:$I$937,Data!$B$2:$B$937,$A6,Data!$E$2:$E$937,$B6) -> 79.860001 | G6: =SUMIFS(Data!$J$2:$J$937,Data!$B$2:$B$937,$A6,Data!$E$2:$E$937,$B6) -> 25 | H6: =SUMIFS(Data!$K$2:$K$937,Data!$B$2:$B$937,$A6,Data!$E$2:$E$937,$B6) -> 10 | I6: =IFERROR(E6/D6,0) -> 0.00023533678 | J6: =IFERROR(F6/D6*1000,0) -> 0.30809829 | K6: =IFERROR(F6/E6,0) -> 1.3091803 | L6: =IFERROR(G6/E6,0) -> 0.40983607 | M6: =IFERROR(H6/E6,0) -> 0.16393443 | N6: =IFERROR(H6/G6,0) -> 0.4 | O6: =IFERROR(F6/G6,0) -> 3.1944 | P6: =IFERROR(F6/H6,0) -> 7.9860001 | Q6: =IFERROR(F6/F$11,0) -> 0.0013603558 | R6: =IFERROR(H6/H$11,0) -> 0.0099700897 | S6: =IFERROR(R6/Q6,0) -> 7.3290309
A7: 936 | B7: F | C7: =COUNTIFS(Data!$B$2:$B$937,$A7,Data!$E$2:$E$937,$B7) -> 178 | D7: =SUMIFS(Data!$G$2:$G$937,Data!$B$2:$B$937,$A7,Data!$E$2:$E$937,$B7) -> 6172243 | E7: =SUMIFS(Data!$H$2:$H$937,Data!$B$2:$B$937,$A7,Data!$E$2:$E$937,$B7) -> 1633 | F7: =SUMIFS(Data!$I$2:$I$937,Data!$B$2:$B$937,$A7,Data!$E$2:$E$937,$B7) -> 2380.36 | G7: =SUMIFS(Data!$J$2:$J$937,Data!$B$2:$B$937,$A7,Data!$E$2:$E$937,$B7) -> 225 | H7: =SUMIFS(Data!$K$2:$K$937,Data!$B$2:$B$937,$A7,Data!$E$2:$E$937,$B7) -> 70 | I7: =IFERROR(E7/D7,0) -> 0.00026457157 | J7: =IFERROR(F7/D7*1000,0) -> 0.38565559 | K7: =IFERROR(F7/E7,0) -> 1.4576607 | L7: =IFERROR(G7/E7,0) -> 0.13778322 | M7: =IFERROR(H7/E7,0) -> 0.042865891 | N7: =IFERROR(H7/G7,0) -> 0.31111111 | O7: =IFERROR(F7/G7,0) -> 10.579378 | P7: =IFERROR(F7/H7,0) -> 34.005143 | Q7: =IFERROR(F7/F$11,0) -> 0.040547665 | R7: =IFERROR(H7/H$11,0) -> 0.069790628 | S7: =IFERROR(R7/Q7,0) -> 1.7211997
A8: 936 | B8: M | C8: =COUNTIFS(Data!$B$2:$B$937,$A8,Data!$E$2:$E$937,$B8) -> 110 | D8: =SUMIFS(Data!$G$2:$G$937,Data!$B$2:$B$937,$A8,Data!$E$2:$E$937,$B8) -> 1625699 | E8: =SUMIFS(Data!$H$2:$H$937,Data!$B$2:$B$937,$A8,Data!$E$2:$E$937,$B8) -> 351 | F8: =SUMIFS(Data!$I$2:$I$937,Data!$B$2:$B$937,$A8,Data!$E$2:$E$937,$B8) -> 513.01 | G8: =SUMIFS(Data!$J$2:$J$937,Data!$B$2:$B$937,$A8,Data!$E$2:$E$937,$B8) -> 131 | H8: =SUMIFS(Data!$K$2:$K$937,Data!$B$2:$B$937,$A8,Data!$E$2:$E$937,$B8) -> 48 | I8: =IFERROR(E8/D8,0) -> 0.00021590713 | J8: =IFERROR(F8/D8*1000,0) -> 0.31556272 | K8: =IFERROR(F8/E8,0) -> 1.461567 | L8: =IFERROR(G8/E8,0) -> 0.37321937 | M8: =IFERROR(H8/E8,0) -> 0.13675214 | N8: =IFERROR(H8/G8,0) -> 0.36641221 | O8: =IFERROR(F8/G8,0) -> 3.9161069 | P8: =IFERROR(F8/H8,0) -> 10.687708 | Q8: =IFERROR(F8/F$11,0) -> 0.0087387444 | R8: =IFERROR(H8/H$11,0) -> 0.047856431 | S8: =IFERROR(R8/Q8,0) -> 5.4763509
A9: 1178 | B9: F | C9: =COUNTIFS(Data!$B$2:$B$937,$A9,Data!$E$2:$E$937,$B9) -> 272 | D9: =SUMIFS(Data!$G$2:$G$937,Data!$B$2:$B$937,$A9,Data!$E$2:$E$937,$B9) -> 108346521 | E9: =SUMIFS(Data!$H$2:$H$937,Data!$B$2:$B$937,$A9,Data!$E$2:$E$937,$B9) -> 22193 | F9: =SUMIFS(Data!$I$2:$I$937,Data!$B$2:$B$937,$A9,Data!$E$2:$E$937,$B9) -> 32052.41 | G9: =SUMIFS(Data!$J$2:$J$937,Data!$B$2:$B$937,$A9,Data!$E$2:$E$937,$B9) -> 1318 | H9: =SUMIFS(Data!$K$2:$K$937,Data!$B$2:$B$937,$A9,Data!$E$2:$E$937,$B9) -> 391 | I9: =IFERROR(E9/D9,0) -> 0.00020483353 | J9: =IFERROR(F9/D9*1000,0) -> 0.29583239 | K9: =IFERROR(F9/E9,0) -> 1.4442576 | L9: =IFERROR(G9/E9,0) -> 0.059388095 | M9: =IFERROR(H9/E9,0) -> 0.017618168 | N9: =IFERROR(H9/G9,0) -> 0.29666161 | O9: =IFERROR(F9/G9,0) -> 24.318976 | P9: =IFERROR(F9/H9,0) -> 81.975473 | Q9: =IFERROR(F9/F$11,0) -> 0.545989 | R9: =IFERROR(H9/H$11,0) -> 0.38983051 | S9: =IFERROR(R9/Q9,0) -> 0.71398967
A10: 1178 | B10: M | C10: =COUNTIFS(Data!$B$2:$B$937,$A10,Data!$E$2:$E$937,$B10) -> 341 | D10: =SUMIFS(Data!$G$2:$G$937,Data!$B$2:$B$937,$A10,Data!$E$2:$E$937,$B10) -> 96353438 | E10: =SUMIFS(Data!$H$2:$H$937,Data!$B$2:$B$937,$A10,Data!$E$2:$E$937,$B10) -> 13875 | F10: =SUMIFS(Data!$I$2:$I$937,Data!$B$2:$B$937,$A10,Data!$E$2:$E$937,$B10) -> 23609.74 | G10: =SUMIFS(Data!$J$2:$J$937,Data!$B$2:$B$937,$A10,Data!$E$2:$E$937,$B10) -> 1339 | H10: =SUMIFS(Data!$K$2:$K$937,Data!$B$2:$B$937,$A10,Data!$E$2:$E$937,$B10) -> 478 | I10: =IFERROR(E10/D10,0) -> 0.00014400109 | J10: =IFERROR(F10/D10*1000,0) -> 0.24503267 | K10: =IFERROR(F10/E10,0) -> 1.7016029 | L10: =IFERROR(G10/E10,0) -> 0.096504505 | M10: =IFERROR(H10/E10,0) -> 0.03445045 | N10: =IFERROR(H10/G10,0) -> 0.35698282 | O10: =IFERROR(F10/G10,0) -> 17.632367 | P10: =IFERROR(F10/H10,0) -> 49.392761 | Q10: =IFERROR(F10/F$11,0) -> 0.40217439 | R10: =IFERROR(H10/H$11,0) -> 0.47657029 | S10: =IFERROR(R10/Q10,0) -> 1.1849842
A11: Total | C11: =SUM(C5:C10) -> 936 | D11: =SUM(D5:D10) -> 212945947 | E11: =SUM(E5:E10) -> 38165 | F11: =SUM(F5:F10) -> 58705.23 | G11: =SUM(G5:G10) -> 3052 | H11: =SUM(H5:H10) -> 1003 | I11: =IFERROR(E11/D11,0) -> 0.00017922389 | J11: =IFERROR(F11/D11*1000,0) -> 0.27568137 | K11: =IFERROR(F11/E11,0) -> 1.5381955 | L11: =IFERROR(G11/E11,0) -> 0.079968558 | M11: =IFERROR(H11/E11,0) -> 0.026280624 | N11: =IFERROR(H11/G11,0) -> 0.32863696 | O11: =IFERROR(F11/G11,0) -> 19.235003 | P11: =IFERROR(F11/H11,0) -> 58.529641 | Q11: =IFERROR(F11/F$11,0) -> 1 | R11: =IFERROR(H11/H$11,0) -> 1 | S11: =IFERROR(R11/Q11,0) -> 1
A13: Efficiency Index = Approved Share ÷ Spend Share. Above 1.0 = the segment returns more approved conversions than its share of budget.

Sheet Interest
A1: Performance by Interest Category (sorted by spend)
A2: Rows with very small spend have unstable ratios – use for direction, not decisions.
A4: Interest ID | B4: Ads | C4: Impressions | D4: Clicks | E4: Spent ($) | F4: Total Conv. | G4: Approved Conv. | H4: CTR % | I4: CPM ($) | J4: CPC ($) | K4: Conv. Rate (CR) | L4: Approved Conv. Rate (ACR) | M4: Approval Rate (AR) | N4: Cost / Total Conv. ($) | O4: Cost / Approved Conv. ($) | P4: Spend Share | Q4: Approved Share | R4: Efficiency Index
A5: 16 | B5: =COUNTIFS(Data!$F$2:$F$937,$A5) -> 116 | C5: =SUMIFS(Data!$G$2:$G$937,Data!$F$2:$F$937,$A5) -> 31691480 | D5: =SUMIFS(Data!$H$2:$H$937,Data!$F$2:$F$937,$A5) -> 5144 | E5: =SUMIFS(Data!$I$2:$I$937,Data!$F$2:$F$937,$A5) -> 8084.91 | F5: =SUMIFS(Data!$J$2:$J$937,Data!$F$2:$F$937,$A5) -> 385 | G5: =SUMIFS(Data!$K$2:$K$937,Data!$F$2:$F$937,$A5) -> 134 | H5: =IFERROR(D5/C5,0) -> 0.00016231492 | I5: =IFERROR(E5/C5*1000,0) -> 0.25511305 | J5: =IFERROR(E5/D5,0) -> 1.5717166 | K5: =IFERROR(F5/D5,0) -> 0.074844479 | L5: =IFERROR(G5/D5,0) -> 0.026049767 | M5: =IFERROR(G5/F5,0) -> 0.34805195 | N5: =IFERROR(E5/F5,0) -> 20.999766 | O5: =IFERROR(E5/G5,0) -> 60.335149 | P5: =IFERROR(E5/E$45,0) -> 0.13772044 | Q5: =IFERROR(G5/G$45,0) -> 0.1335992 | R5: =IFERROR(Q5/P5,0) -> 0.97007535
A6: 27 | B6: =COUNTIFS(Data!$F$2:$F$937,$A6) -> 52 | C6: =SUMIFS(Data!$G$2:$G$937,Data!$F$2:$F$937,$A6) -> 16342554 | D6: =SUMIFS(Data!$H$2:$H$937,Data!$F$2:$F$937,$A6) -> 3409 | E6: =SUMIFS(Data!$I$2:$I$937,Data!$F$2:$F$937,$A6) -> 5176.17 | F6: =SUMIFS(Data!$J$2:$J$937,Data!$F$2:$F$937,$A6) -> 232 | G6: =SUMIFS(Data!$K$2:$K$937,Data!$F$2:$F$937,$A6) -> 53 | H6: =IFERROR(D6/C6,0) -> 0.00020859653 | I6: =IFERROR(E6/C6*1000,0) -> 0.31672956 | J6: =IFERROR(E6/D6,0) -> 1.5183837 | K6: =IFERROR(F6/D6,0) -> 0.068055148 | L6: =IFERROR(G6/D6,0) -> 0.015547081 | M6: =IFERROR(G6/F6,0) -> 0.22844828 | N6: =IFERROR(E6/F6,0) -> 22.311078 | O6: =IFERROR(E6/G6,0) -> 97.663585 | P6: =IFERROR(E6/E$45,0) -> 0.088172212 | Q6: =IFERROR(G6/G$45,0) -> 0.052841476 | R6: =IFERROR(Q6/P6,0) -> 0.59929851
A7: 10 | B7: =COUNTIFS(Data!$F$2:$F$937,$A7) -> 69 | C7: =SUMIFS(Data!$G$2:$G$937,Data!$F$2:$F$937,$A7) -> 17935367 | D7: =SUMIFS(Data!$H$2:$H$937,Data!$F$2:$F$937,$A7) -> 3317 | E7: =SUMIFS(Data!$I$2:$I$937,Data!$F$2:$F$937,$A7) -> 5086.38 | F7: =SUMIFS(Data!$J$2:$J$937,Data!$F$2:$F$937,$A7) -> 253 | G7: =SUMIFS(Data!$K$2:$K$937,Data!$F$2:$F$937,$A7) -> 83 | H7: =IFERROR(D7/C7,0) -> 0.00018494185 | I7: =IFERROR(E7/C7*1000,0) -> 0.28359498 | J7: =IFERROR(E7/D7,0) -> 1.5334278 | K7: =IFERROR(F7/D7,0) -> 0.076273741 | L7: =IFERROR(G7/D7,0) -> 0.025022611 | M7: =IFERROR(G7/F7,0) -> 0.32806324 | N7: =IFERROR(E7/F7,0) -> 20.104269 | O7: =IFERROR(E7/G7,0) -> 61.281687 | P7: =IFERROR(E7/E$45,0) -> 0.086642706 | Q7: =IFERROR(G7/G$45,0) -> 0.082751745 | R7: =IFERROR(Q7/P7,0) -> 0.95509187
A8: 29 | B8: =COUNTIFS(Data!$F$2:$F$937,$A8) -> 61 | C8: =SUMIFS(Data!$G$2:$G$937,Data!$F$2:$F$937,$A8) -> 18720765 | D8: =SUMIFS(Data!$H$2:$H$937,Data!$F$2:$F$937,$A8) -> 3315 | E8: =SUMIFS(Data!$I$2:$I$937,Data!$F$2:$F$937,$A8) -> 5045.19 | F8: =SUMIFS(Data!$J$2:$J$937,Data!$F$2:$F$937,$A8) -> 289 | G8: =SUMIFS(Data!$K$2:$K$937,Data!$F$2:$F$937,$A8) -> 124 | H8: =IFERROR(D8/C8,0) -> 0.0001770761 | I8: =IFERROR(E8/C8*1000,0) -> 0.269497 | J8: =IFERROR(E8/D8,0) -> 1.5219276 | K8: =IFERROR(F8/D8,0) -> 0.087179487 | L8: =IFERROR(G8/D8,0) -> 0.037405732 | M8: =IFERROR(G8/F8,0) -> 0.42906574 | N8: =IFERROR(E8/F8,0) -> 17.457405 | O8: =IFERROR(E8/G8,0) -> 40.687016 | P8: =IFERROR(E8/E$45,0) -> 0.085941065 | Q8: =IFERROR(G8/G$45,0) -> 0.12362911 | R8: =IFERROR(Q8/P8,0) -> 1.4385336
A9: 28 | B9: =COUNTIFS(Data!$F$2:$F$937,$A9) -> 43 | C9: =SUMIFS(Data!$G$2:$G$937,Data!$F$2:$F$937,$A9) -> 10947059 | D9: =SUMIFS(Data!$H$2:$H$937,Data!$F$2:$F$937,$A9) -> 2025 | E9: =SUMIFS(Data!$I$2:$I$937,Data!$F$2:$F$937,$A9) -> 3205.85 | F9: =SUMIFS(Data!$J$2:$J$937,Data!$F$2:$F$937,$A9) -> 138 | G9: =SUMIFS(Data!$K$2:$K$937,Data!$F$2:$F$937,$A9) -> 41 | H9: =IFERROR(D9/C9,0) -> 0.00018498119 | I9: =IFERROR(E9/C9*1000,0) -> 0.29285034 | J9: =IFERROR(E9/D9,0) -> 1.5831358 | K9: =IFERROR(F9/D9,0) -> 0.068148148 | L9: =IFERROR(G9/D9,0) -> 0.020246914 | M9: =IFERROR(G9/F9,0) -> 0.29710145 | N9: =IFERROR(E9/F9,0) -> 23.230797 | O9: =IFERROR(E9/G9,0) -> 78.191464 | P9: =IFERROR(E9/E$45,0) -> 0.054609274 | Q9: =IFERROR(G9/G$45,0) -> 0.040877368 | R9: =IFERROR(Q9/P9,0) -> 0.7485426
A10: 15 | B10: =COUNTIFS(Data!$F$2:$F$937,$A10) -> 39 | C10: =SUMIFS(Data!$G$2:$G$937,Data!$F$2:$F$937,$A10) -> 10712519 | D10: =SUMIFS(Data!$H$2:$H$937,Data!$F$2:$F$937,$A10) -> 1609 | E10: =SUMIFS(Data!$I$2:$I$937,Data!$F$2:$F$937,$A10) -> 2597.26 | F10: =SUMIFS(Data!$J$2:$J$937,Data!$F$2:$F$937,$A10) -> 182 | G10: =SUMIFS(Data!$K$2:$K$937,Data!$F$2:$F$937,$A10) -> 57 | H10: =IFERROR(D10/C10,0) -> 0.0001501981 | I10: =IFERROR(E10/C10*1000,0) -> 0.24245091 | J10: =IFERROR(E10/D10,0) -> 1.6142076 | K10: =IFERROR(F10/D10,0) -> 0.11311374 | L10: =IFERROR(G10/D10,0) -> 0.03542573 | M10: =IFERROR(G10/F10,0) -> 0.31318681 | N10: =IFERROR(E10/F10,0) -> 14.270659 | O10: =IFERROR(E10/G10,0) -> 45.565965 | P10: =IFERROR(E10/E$45,0) -> 0.044242395 | Q10: =IFERROR(G10/G$45,0) -> 0.056829511 | R10: =IFERROR(Q10/P10,0) -> 1.2845035
A11: 63 | B11: =COUNTIFS(Data!$F$2:$F$937,$A11) -> 38 | C11: =SUMIFS(Data!$G$2:$G$937,Data!$F$2:$F$937,$A11) -> 8336174 | D11: =SUMIFS(Data!$H$2:$H$937,Data!$F$2:$F$937,$A11) -> 1675 | E11: =SUMIFS(Data!$I$2:$I$937,Data!$F$2:$F$937,$A11) -> 2484.06 | F11: =SUMIFS(Data!$J$2:$J$937,Data!$F$2:$F$937,$A11) -> 93 | G11: =SUMIFS(Data!$K$2:$K$937,Data!$F$2:$F$937,$A11) -> 30 | H11: =IFERROR(D11/C11,0) -> 0.00020093151 | I11: =IFERROR(E11/C11*1000,0) -> 0.29798562 | J11: =IFERROR(E11/D11,0) -> 1.4830209 | K11: =IFERROR(F11/D11,0) -> 0.055522388 | L11: =IFERROR(G11/D11,0) -> 0.017910448 | M11: =IFERROR(G11/F11,0) -> 0.32258065 | N11: =IFERROR(E11/F11,0) -> 26.710323 | O11: =IFERROR(E11/G11,0) -> 82.802 | P11: =IFERROR(E11/E$45,0) -> 0.042314118 | Q11: =IFERROR(G11/G$45,0) -> 0.029910269 | R11: =IFERROR(Q11/P11,0) -> 0.70686265
A12: 18 | B12: =COUNTIFS(Data!$F$2:$F$937,$A12) -> 34 | C12: =SUMIFS(Data!$G$2:$G$937,Data!$F$2:$F$937,$A12) -> 8631584 | D12: =SUMIFS(Data!$H$2:$H$937,Data!$F$2:$F$937,$A12) -> 1524 | E12: =SUMIFS(Data!$I$2:$I$937,Data!$F$2:$F$937,$A12) -> 2425.07 | F12: =SUMIFS(Data!$J$2:$J$937,Data!$F$2:$F$937,$A12) -> 75 | G12: =SUMIFS(Data!$K$2:$K$937,Data!$F$2:$F$937,$A12) -> 31 | H12: =IFERROR(D12/C12,0) -> 0.00017656087 | I12: =IFERROR(E12/C12*1000,0) -> 0.28095307 | J12: =IFERROR(E12/D12,0) -> 1.5912533 | K12: =IFERROR(F12/D12,0) -> 0.049212598 | L12: =IFERROR(G12/D12,0) -> 0.020341207 | M12: =IFERROR(G12/F12,0) -> 0.41333333 | N12: =IFERROR(E12/F12,0) -> 32.334267 | O12: =IFERROR(E12/G12,0) -> 78.228065 | P12: =IFERROR(E12/E$45,0) -> 0.041309267 | Q12: =IFERROR(G12/G$45,0) -> 0.030907278 | R12: =IFERROR(Q12/P12,0) -> 0.74819237
A13: 32 | B13: =COUNTIFS(Data!$F$2:$F$937,$A13) -> 24 | C13: =SUMIFS(Data!$G$2:$G$937,Data!$F$2:$F$937,$A13) -> 6439439 | D13: =SUMIFS(Data!$H$2:$H$937,Data!$F$2:$F$937,$A13) -> 1138 | E13: =SUMIFS(Data!$I$2:$I$937,Data!$F$2:$F$937,$A13) -> 1970.53 | F13: =SUMIFS(Data!$J$2:$J$937,Data!$F$2:$F$937,$A13) -> 67 | G13: =SUMIFS(Data!$K$2:$K$937,Data!$F$2:$F$937,$A13) -> 32 | H13: =IFERROR(D13/C13,0) -> 0.00017672347 | I13: =IFERROR(E13/C13*1000,0) -> 0.30600958 | J13: =IFERROR(E13/D13,0) -> 1.7315729 | K13: =IFERROR(F13/D13,0) -> 0.05887522 | L13: =IFERROR(G13/D13,0) -> 0.028119508 | M13: =IFERROR(G13/F13,0) -> 0.47761194 | N13: =IFERROR(E13/F13,0) -> 29.410896 | O13: =IFERROR(E13/G13,0) -> 61.579063 | P13: =IFERROR(E13/E$45,0) -> 0.033566515 | Q13: =IFERROR(G13/G$45,0) -> 0.031904287 | R13: =IFERROR(Q13/P13,0) -> 0.95047957
A14: 20 | B14: =COUNTIFS(Data!$F$2:$F$937,$A14) -> 39 | C14: =SUMIFS(Data!$G$2:$G$937,Data!$F$2:$F$937,$A14) -> 6891466 | D14: =SUMIFS(Data!$H$2:$H$937,Data!$F$2:$F$937,$A14) -> 1234 | E14: =SUMIFS(Data!$I$2:$I$937,Data!$F$2:$F$937,$A14) -> 1960.77 | F14: =SUMIFS(Data!$J$2:$J$937,Data!$F$2:$F$937,$A14) -> 120 | G14: =SUMIFS(Data!$K$2:$K$937,Data!$F$2:$F$937,$A14) -> 45 | H14: =IFERROR(D14/C14,0) -> 0.00017906205 | I14: =IFERROR(E14/C14*1000,0) -> 0.28452146 | J14: =IFERROR(E14/D14,0) -> 1.5889546 | K14: =IFERROR(F14/D14,0) -> 0.097244733 | L14: =IFERROR(G14/D14,0) -> 0.036466775 | M14: =IFERROR(G14/F14,0) -> 0.375 | N14: =IFERROR(E14/F14,0) -> 16.33975 | O14: =IFERROR(E14/G14,0) -> 43.572667 | P14: =IFERROR(E14/E$45,0) -> 0.033400261 | Q14: =IFERROR(G14/G$45,0) -> 0.044865404 | R14: =IFERROR(Q14/P14,0) -> 1.3432651
A15: 19 | B15: =COUNTIFS(Data!$F$2:$F$937,$A15) -> 28 | C15: =SUMIFS(Data!$G$2:$G$937,Data!$F$2:$F$937,$A15) -> 6081495 | D15: =SUMIFS(Data!$H$2:$H$937,Data!$F$2:$F$937,$A15) -> 1188 | E15: =SUMIFS(Data!$I$2:$I$937,Data!$F$2:$F$937,$A15) -> 1940.36 | F15: =SUMIFS(Data!$J$2:$J$937,Data!$F$2:$F$937,$A15) -> 93 | G15: =SUMIFS(Data!$K$2:$K$937,Data!$F$2:$F$937,$A15) -> 33 | H15: =IFERROR(D15/C15,0) -> 0.0001953467 | I15: =IFERROR(E15/C15*1000,0) -> 0.3190597 | J15: =IFERROR(E15/D15,0) -> 1.6332997 | K15: =IFERROR(F15/D15,0) -> 0.078282828 | L15: =IFERROR(G15/D15,0) -> 0.027777778 | M15: =IFERROR(G15/F15,0) -> 0.35483871 | N15: =IFERROR(E15/F15,0) -> 20.864086 | O15: =IFERROR(E15/G15,0) -> 58.798788 | P15: =IFERROR(E15/E$45,0) -> 0.033052592 | Q15: =IFERROR(G15/G$45,0) -> 0.032901296 | R15: =IFERROR(Q15/P15,0) -> 0.99542258
A16: 25 | B16: =COUNTIFS(Data!$F$2:$F$937,$A16) -> 24 | C16: =SUMIFS(Data!$G$2:$G$937,Data!$F$2:$F$937,$A16) -> 5250418 | D16: =SUMIFS(Data!$H$2:$H$937,Data!$F$2:$F$937,$A16) -> 1066 | E16: =SUMIFS(Data!$I$2:$I$937,Data!$F$2:$F$937,$A16) -> 1603.86 | F16: =SUMIFS(Data!$J$2:$J$937,Data!$F$2:$F$937,$A16) -> 76 | G16: =SUMIFS(Data!$K$2:$K$937,Data!$F$2:$F$937,$A16) -> 19 | H16: =IFERROR(D16/C16,0) -> 0.00020303145 | I16: =IFERROR(E16/C16*1000,0) -> 0.30547282 | J16: =IFERROR(E16/D16,0) -> 1.5045591 | K16: =IFERROR(F16/D16,0) -> 0.071294559 | L16: =IFERROR(G16/D16,0) -> 0.01782364 | M16: =IFERROR(G16/F16,0) -> 0.25 | N16: =IFERROR(E16/F16,0) -> 21.103421 | O16: =IFERROR(E16/G16,0) -> 84.413684 | P16: =IFERROR(E16/E$45,0) -> 0.027320564 | Q16: =IFERROR(G16/G$45,0) -> 0.01894317 | R16: =IFERROR(Q16/P16,0) -> 0.69336674
... A44: 36 | B44: =COUNTIFS(Data!$F$2:$F$937,$A44) -> 15 | C44: =SUMIFS(Data!$G$2:$G$937,Data!$F$2:$F$937,$A44) -> 918299 | D44: =SUMIFS(Data!$H$2:$H$937,Data!$F$2:$F$937,$A44) -> 128 | E44: =SUMIFS(Data!$I$2:$I$937,Data!$F$2:$F$937,$A44) -> 205.74 | F44: =SUMIFS(Data!$J$2:$J$937,Data!$F$2:$F$937,$A44) -> 23 | G44: =SUMIFS(Data!$K$2:$K$937,Data!$F$2:$F$937,$A44) -> 8 | H44: =IFERROR(D44/C44,0) -> 0.00013938815 | I44: =IFERROR(E44/C44*1000,0) -> 0.22404467 | J44: =IFERROR(E44/D44,0) -> 1.6073437 | K44: =IFERROR(F44/D44,0) -> 0.1796875 | L44: =IFERROR(G44/D44,0) -> 0.0625 | M44: =IFERROR(G44/F44,0) -> 0.34782609 | N44: =IFERROR(E44/F44,0) -> 8.9452174 | O44: =IFERROR(E44/G44,0) -> 25.7175 | P44: =IFERROR(E44/E$45,0) -> 0.0035046281 | Q44: =IFERROR(G44/G$45,0) -> 0.0079760718 | R44: =IFERROR(Q44/P44,0) -> 2.2758682
A45: Total | B45: =SUM(B5:B44) -> 936 | C45: =SUM(C5:C44) -> 212945947 | D45: =SUM(D5:D44) -> 38165 | E45: =SUM(E5:E44) -> 58705.23 | F45: =SUM(F5:F44) -> 3052 | G45: =SUM(G5:G44) -> 1003 | H45: =IFERROR(D45/C45,0) -> 0.00017922389 | I45: =IFERROR(E45/C45*1000,0) -> 0.27568137 | J45: =IFERROR(E45/D45,0) -> 1.5381955 | K45: =IFERROR(F45/D45,0) -> 0.079968558 | L45: =IFERROR(G45/D45,0) -> 0.026280624 | M45: =IFERROR(G45/F45,0) -> 0.32863696 | N45: =IFERROR(E45/F45,0) -> 19.235003 | O45: =IFERROR(E45/G45,0) -> 58.529641 | P45: =IFERROR(E45/E$45,0) -> 1 | Q45: =IFERROR(G45/G$45,0) -> 1 | R45: =IFERROR(Q45/P45,0) -> 1
A47: Efficiency Index = Approved Share ÷ Spend Share. Above 1.0 = the segment returns more approved conversions than its share of budget.

Sheet Reconciliation
A1: Scope: raw CSV vs the 936-ad analysis scope
A2: Raw CSV figures are hardcoded inputs (blue). The 207 removed ads all have 0 clicks and $0 spend.
A4: Metric | B4: Raw CSV (1,143 ads) | C4: Analysis scope (936 ads) | D4: Removed (207 ads)
A5: Ads | B5: 1143 | C5: =Overview!B5 -> 936 | D5: =B5-C5 -> 207
A6: Distinct fb campaigns | B6: 691 | C6: =Overview!B6 -> 543 | D6: =B6-C6 -> 148
A7: Impressions | B7: 213434828 | C7: =Overview!B7 -> 212945947 | D7: =B7-C7 -> 488881
A8: Clicks | B8: 38165 | C8: =Overview!B8 -> 38165 | D8: =B8-C8 -> 0
A9: Spent ($) | B9: 58705.23 | C9: =Overview!B9 -> 58705.23 | D9: =B9-C9 -> 4.1795e-05
A10: Total Conversions | B10: 3264 | C10: =Overview!B10 -> 3052 | D10: =B10-C10 -> 212
A11: Approved Conversions | B11: 1079 | C11: =Overview!B11 -> 1003 | D11: =B11-C11 -> 76
A13: Removed ads: 0 clicks, $0 spend, 488,881 impressions, 212 total and 76 approved conversions (no click attributed).

Sheet Metric Definitions
A1: Metrics used
A3: Metric | B3: Formula | C3: How to read it
A4: CTR | B4: Clicks ÷ Impressions | C4: Ad relevance / attention
A5: CPM | B5: Spend ÷ Impressions × 1,000 | C5: Cost of reach
A6: CPC | B6: Spend ÷ Clicks | C6: Cost of traffic
A7: CR | B7: Total Conv. ÷ Clicks | C7: Click-to-lead quality (can exceed 100% on tiny samples or view-through)
A8: ACR | B8: Approved Conv. ÷ Clicks | C8: Click-to-sale quality
A9: AR | B9: Approved ÷ Total Conv. | C9: Lead-to-sale closing rate
A10: Cost / Total Conv. | B10: Spend ÷ Total Conv. | C10: Cost per lead
A11: Cost / Approved Conv. (CPA) | B11: Spend ÷ Approved Conv. | C11: Cost per sale – primary efficiency KPI
A12: Spend Share / Approved Share | B12: Segment ÷ Grand total | C12: Budget vs results distribution
A13: Efficiency Index | B13: Approved Share ÷ Spend Share | C13: >1 over-delivers, <1 under-delivers

Sheet Gender Theory by Campaign
A1: Are men under-invested? Gender comparison inside each campaign
A2: Shares are within each campaign. Efficiency index = share of approved / share of spend (above 1 = under-invested relative to results). Campaign 916 is small (35 ads, 16 approved).
A4: Campaign | B4: Gender | C4: Ads | D4: Clicks | E4: Spent ($) | F4: Total Conv. | G4: Approved Conv. | H4: Share of Ads | I4: Share of Spend | J4: Share of Approved | K4: ACR | L4: AR | M4: Cost / Approved Conv. ($) | N4: Efficiency Index | O4: Spend per Ad ($)
A5: 916 | B5: M | C5: =COUNTIFS(Data!$B$2:$B$937,$A5,Data!$E$2:$E$937,$B5) -> 22 | D5: =SUMIFS(Data!$H$2:$H$937,Data!$B$2:$B$937,$A5,Data!$E$2:$E$937,$B5) -> 61 | E5: =SUMIFS(Data!$I$2:$I$937,Data!$B$2:$B$937,$A5,Data!$E$2:$E$937,$B5) -> 79.860001 | F5: =SUMIFS(Data!$J$2:$J$937,Data!$B$2:$B$937,$A5,Data!$E$2:$E$937,$B5) -> 25 | G5: =SUMIFS(Data!$K$2:$K$937,Data!$B$2:$B$937,$A5,Data!$E$2:$E$937,$B5) -> 10 | H5: =C5/COUNTIFS(Data!$B$2:$B$937,$A5) -> 0.62857143 | I5: =E5/SUMIFS(Data!$I$2:$I$937,Data!$B$2:$B$937,$A5) -> 0.5334313 | J5: =G5/SUMIFS(Data!$K$2:$K$937,Data!$B$2:$B$937,$A5) -> 0.625 | K5: =IFERROR(G5/D5,0) -> 0.16393443 | L5: =IFERROR(G5/F5,0) -> 0.4 | M5: =IFERROR(E5/G5,0) -> 7.9860001 | N5: =IFERROR(J5/I5,0) -> 1.1716598 | O5: =IFERROR(E5/C5,0) -> 3.63
A6: 916 | B6: F | C6: =COUNTIFS(Data!$B$2:$B$937,$A6,Data!$E$2:$E$937,$B6) -> 13 | D6: =SUMIFS(Data!$H$2:$H$937,Data!$B$2:$B$937,$A6,Data!$E$2:$E$937,$B6) -> 52 | E6: =SUMIFS(Data!$I$2:$I$937,Data!$B$2:$B$937,$A6,Data!$E$2:$E$937,$B6) -> 69.85 | F6: =SUMIFS(Data!$J$2:$J$937,Data!$B$2:$B$937,$A6,Data!$E$2:$E$937,$B6) -> 14 | G6: =SUMIFS(Data!$K$2:$K$937,Data!$B$2:$B$937,$A6,Data!$E$2:$E$937,$B6) -> 6 | H6: =C6/COUNTIFS(Data!$B$2:$B$937,$A6) -> 0.37142857 | I6: =E6/SUMIFS(Data!$I$2:$I$937,Data!$B$2:$B$937,$A6) -> 0.4665687 | J6: =G6/SUMIFS(Data!$K$2:$K$937,Data!$B$2:$B$937,$A6) -> 0.375 | K6: =IFERROR(G6/D6,0) -> 0.11538462 | L6: =IFERROR(G6/F6,0) -> 0.42857143 | M6: =IFERROR(E6/G6,0) -> 11.641667 | N6: =IFERROR(J6/I6,0) -> 0.80374016 | O6: =IFERROR(E6/C6,0) -> 5.3730769
A7: 936 | B7: M | C7: =COUNTIFS(Data!$B$2:$B$937,$A7,Data!$E$2:$E$937,$B7) -> 110 | D7: =SUMIFS(Data!$H$2:$H$937,Data!$B$2:$B$937,$A7,Data!$E$2:$E$937,$B7) -> 351 | E7: =SUMIFS(Data!$I$2:$I$937,Data!$B$2:$B$937,$A7,Data!$E$2:$E$937,$B7) -> 513.01 | F7: =SUMIFS(Data!$J$2:$J$937,Data!$B$2:$B$937,$A7,Data!$E$2:$E$937,$B7) -> 131 | G7: =SUMIFS(Data!$K$2:$K$937,Data!$B$2:$B$937,$A7,Data!$E$2:$E$937,$B7) -> 48 | H7: =C7/COUNTIFS(Data!$B$2:$B$937,$A7) -> 0.38194444 | I7: =E7/SUMIFS(Data!$I$2:$I$937,Data!$B$2:$B$937,$A7) -> 0.17730536 | J7: =G7/SUMIFS(Data!$K$2:$K$937,Data!$B$2:$B$937,$A7) -> 0.40677966 | K7: =IFERROR(G7/D7,0) -> 0.13675214 | L7: =IFERROR(G7/F7,0) -> 0.36641221 | M7: =IFERROR(E7/G7,0) -> 10.687708 | N7: =IFERROR(J7/I7,0) -> 2.2942322 | O7: =IFERROR(E7/C7,0) -> 4.6637273
A8: 936 | B8: F | C8: =COUNTIFS(Data!$B$2:$B$937,$A8,Data!$E$2:$E$937,$B8) -> 178 | D8: =SUMIFS(Data!$H$2:$H$937,Data!$B$2:$B$937,$A8,Data!$E$2:$E$937,$B8) -> 1633 | E8: =SUMIFS(Data!$I$2:$I$937,Data!$B$2:$B$937,$A8,Data!$E$2:$E$937,$B8) -> 2380.36 | F8: =SUMIFS(Data!$J$2:$J$937,Data!$B$2:$B$937,$A8,Data!$E$2:$E$937,$B8) -> 225 | G8: =SUMIFS(Data!$K$2:$K$937,Data!$B$2:$B$937,$A8,Data!$E$2:$E$937,$B8) -> 70 | H8: =C8/COUNTIFS(Data!$B$2:$B$937,$A8) -> 0.61805556 | I8: =E8/SUMIFS(Data!$I$2:$I$937,Data!$B$2:$B$937,$A8) -> 0.82269464 | J8: =G8/SUMIFS(Data!$K$2:$K$937,Data!$B$2:$B$937,$A8) -> 0.59322034 | K8: =IFERROR(G8/D8,0) -> 0.042865891 | L8: =IFERROR(G8/F8,0) -> 0.31111111 | M8: =IFERROR(E8/G8,0) -> 34.005143 | N8: =IFERROR(J8/I8,0) -> 0.72106989 | O8: =IFERROR(E8/C8,0) -> 13.372809
A9: 1178 | B9: M | C9: =COUNTIFS(Data!$B$2:$B$937,$A9,Data!$E$2:$E$937,$B9) -> 341 | D9: =SUMIFS(Data!$H$2:$H$937,Data!$B$2:$B$937,$A9,Data!$E$2:$E$937,$B9) -> 13875 | E9: =SUMIFS(Data!$I$2:$I$937,Data!$B$2:$B$937,$A9,Data!$E$2:$E$937,$B9) -> 23609.74 | F9: =SUMIFS(Data!$J$2:$J$937,Data!$B$2:$B$937,$A9,Data!$E$2:$E$937,$B9) -> 1339 | G9: =SUMIFS(Data!$K$2:$K$937,Data!$B$2:$B$937,$A9,Data!$E$2:$E$937,$B9) -> 478 | H9: =C9/COUNTIFS(Data!$B$2:$B$937,$A9) -> 0.55628059 | I9: =E9/SUMIFS(Data!$I$2:$I$937,Data!$B$2:$B$937,$A9) -> 0.42416148 | J9: =G9/SUMIFS(Data!$K$2:$K$937,Data!$B$2:$B$937,$A9) -> 0.55005754 | K9: =IFERROR(G9/D9,0) -> 0.03445045 | L9: =IFERROR(G9/F9,0) -> 0.35698282 | M9: =IFERROR(E9/G9,0) -> 49.392761 | N9: =IFERROR(J9/I9,0) -> 1.2968116 | O9: =IFERROR(E9/C9,0) -> 69.236774
A10: 1178 | B10: F | C10: =COUNTIFS(Data!$B$2:$B$937,$A10,Data!$E$2:$E$937,$B10) -> 272 | D10: =SUMIFS(Data!$H$2:$H$937,Data!$B$2:$B$937,$A10,Data!$E$2:$E$937,$B10) -> 22193 | E10: =SUMIFS(Data!$I$2:$I$937,Data!$B$2:$B$937,$A10,Data!$E$2:$E$937,$B10) -> 32052.41 | F10: =SUMIFS(Data!$J$2:$J$937,Data!$B$2:$B$937,$A10,Data!$E$2:$E$937,$B10) -> 1318 | G10: =SUMIFS(Data!$K$2:$K$937,Data!$B$2:$B$937,$A10,Data!$E$2:$E$937,$B10) -> 391 | H10: =C10/COUNTIFS(Data!$B$2:$B$937,$A10) -> 0.44371941 | I10: =E10/SUMIFS(Data!$I$2:$I$937,Data!$B$2:$B$937,$A10) -> 0.57583852 | J10: =G10/SUMIFS(Data!$K$2:$K$937,Data!$B$2:$B$937,$A10) -> 0.44994246 | K10: =IFERROR(G10/D10,0) -> 0.017618168 | L10: =IFERROR(G10/F10,0) -> 0.29666161 | M10: =IFERROR(E10/G10,0) -> 81.975473 | N10: =IFERROR(J10/I10,0) -> 0.78136917 | O10: =IFERROR(E10/C10,0) -> 117.83974
A12: Campaign | B12: Men / Women: Cost per Approved | C12: Men / Women: ACR | D12: Men / Women: Spend per Ad | E12: Men - Women: AR (pts)
A13: 916 | B13: =M5/M6 -> 0.68598426 | C13: =K5/K6 -> 1.420765 | D13: =O5/O6 -> 0.67559055 | E13: =(L5-L6)*100 -> -2.8571429
A14: 936 | B14: =M7/M8 -> 0.31429682 | C14: =K7/K8 -> 3.190232 | D14: =O7/O8 -> 0.34874702 | E14: =(L7-L8)*100 -> 5.5301103
A15: 1178 | B15: =M9/M10 -> 0.60253097 | C15: =K9/K10 -> 1.9553935 | D15: =O9/O10 -> 0.58755028 | E15: =(L9-L10)*100 -> 6.0321215

Sheet Men 30-34 by Campaign
A1: Is the campaign gap just a Men 30-34 mix effect? Men 30-34 vs everyone else, by campaign
A2: Shares are within each campaign. Campaign 916 men 30-34 = 10 ads and 4 approved conversions: directional only.
A4: Campaign | B4: Group | C4: Ads | D4: Clicks | E4: Spent ($) | F4: Approved Conv. | G4: Share of Ads | H4: Share of Spend | I4: Share of Approved | J4: ACR | K4: Cost / Approved Conv. ($)
A5: 916 | B5: Men 30-34 | C5: =COUNTIFS(Data!$B$2:$B$937,$A5,Data!$D$2:$D$937,"30-34",Data!$E$2:$E$937,"M") -> 10 | D5: =SUMIFS(Data!$H$2:$H$937,Data!$B$2:$B$937,$A5,Data!$D$2:$D$937,"30-34",Data!$E$2:$E$937,"M") -> 21 | E5: =SUMIFS(Data!$I$2:$I$937,Data!$B$2:$B$937,$A5,Data!$D$2:$D$937,"30-34",Data!$E$2:$E$937,"M") -> 27.34 | F5: =SUMIFS(Data!$K$2:$K$937,Data!$B$2:$B$937,$A5,Data!$D$2:$D$937,"30-34",Data!$E$2:$E$937,"M") -> 4 | G5: =C5/(C5+C6) -> 0.28571429 | H5: =E5/(E5+E6) -> 0.18261973 | I5: =F5/(F5+F6) -> 0.25 | J5: =IFERROR(F5/D5,0) -> 0.19047619 | K5: =IFERROR(E5/F5,0) -> 6.835
A6: 916 | B6: Everyone else | C6: =COUNTIFS(Data!$B$2:$B$937,$A6)-C5 -> 25 | D6: =SUMIFS(Data!$H$2:$H$937,Data!$B$2:$B$937,$A6)-D5 -> 92 | E6: =SUMIFS(Data!$I$2:$I$937,Data!$B$2:$B$937,$A6)-E5 -> 122.37 | F6: =SUMIFS(Data!$K$2:$K$937,Data!$B$2:$B$937,$A6)-F5 -> 12 | G6: =C6/(C5+C6) -> 0.71428571 | H6: =E6/(E5+E6) -> 0.81738027 | I6: =F6/(F5+F6) -> 0.75 | J6: =IFERROR(F6/D6,0) -> 0.13043478 | K6: =IFERROR(E6/F6,0) -> 10.1975
A7: 936 | B7: Men 30-34 | C7: =COUNTIFS(Data!$B$2:$B$937,$A7,Data!$D$2:$D$937,"30-34",Data!$E$2:$E$937,"M") -> 41 | D7: =SUMIFS(Data!$H$2:$H$937,Data!$B$2:$B$937,$A7,Data!$D$2:$D$937,"30-34",Data!$E$2:$E$937,"M") -> 100 | E7: =SUMIFS(Data!$I$2:$I$937,Data!$B$2:$B$937,$A7,Data!$D$2:$D$937,"30-34",Data!$E$2:$E$937,"M") -> 137.51 | F7: =SUMIFS(Data!$K$2:$K$937,Data!$B$2:$B$937,$A7,Data!$D$2:$D$937,"30-34",Data!$E$2:$E$937,"M") -> 19 | G7: =C7/(C7+C8) -> 0.14236111 | H7: =E7/(E7+E8) -> 0.047525895 | I7: =F7/(F7+F8) -> 0.16101695 | J7: =IFERROR(F7/D7,0) -> 0.19 | K7: =IFERROR(E7/F7,0) -> 7.2373684
A8: 936 | B8: Everyone else | C8: =COUNTIFS(Data!$B$2:$B$937,$A8)-C7 -> 247 | D8: =SUMIFS(Data!$H$2:$H$937,Data!$B$2:$B$937,$A8)-D7 -> 1884 | E8: =SUMIFS(Data!$I$2:$I$937,Data!$B$2:$B$937,$A8)-E7 -> 2755.86 | F8: =SUMIFS(Data!$K$2:$K$937,Data!$B$2:$B$937,$A8)-F7 -> 99 | G8: =C8/(C7+C8) -> 0.85763889 | H8: =E8/(E7+E8) -> 0.9524741 | I8: =F8/(F7+F8) -> 0.83898305 | J8: =IFERROR(F8/D8,0) -> 0.052547771 | K8: =IFERROR(E8/F8,0) -> 27.83697
A9: 1178 | B9: Men 30-34 | C9: =COUNTIFS(Data!$B$2:$B$937,$A9,Data!$D$2:$D$937,"30-34",Data!$E$2:$E$937,"M") -> 107 | D9: =SUMIFS(Data!$H$2:$H$937,Data!$B$2:$B$937,$A9,Data!$D$2:$D$937,"30-34",Data!$E$2:$E$937,"M") -> 4263 | E9: =SUMIFS(Data!$I$2:$I$937,Data!$B$2:$B$937,$A9,Data!$D$2:$D$937,"30-34",Data!$E$2:$E$937,"M") -> 7476.07 | F9: =SUMIFS(Data!$K$2:$K$937,Data!$B$2:$B$937,$A9,Data!$D$2:$D$937,"30-34",Data!$E$2:$E$937,"M") -> 240 | G9: =C9/(C9+C10) -> 0.17455139 | H9: =E9/(E9+E10) -> 0.13431156 | I9: =F9/(F9+F10) -> 0.27617952 | J9: =IFERROR(F9/D9,0) -> 0.056298381 | K9: =IFERROR(E9/F9,0) -> 31.150292
A10: 1178 | B10: Everyone else | C10: =COUNTIFS(Data!$B$2:$B$937,$A10)-C9 -> 506 | D10: =SUMIFS(Data!$H$2:$H$937,Data!$B$2:$B$937,$A10)-D9 -> 31805 | E10: =SUMIFS(Data!$I$2:$I$937,Data!$B$2:$B$937,$A10)-E9 -> 48186.08 | F10: =SUMIFS(Data!$K$2:$K$937,Data!$B$2:$B$937,$A10)-F9 -> 629 | G10: =C10/(C9+C10) -> 0.82544861 | H10: =E10/(E9+E10) -> 0.86568844 | I10: =F10/(F9+F10) -> 0.72382048 | J10: =IFERROR(F10/D10,0) -> 0.019776765 | K10: =IFERROR(E10/F10,0) -> 76.60744
A12: Mix test: what would the 1178 cost per approved conversion be if its spend mix matched another campaign?
A13: Campaign mix applied | B13: Men 30-34 share of spend | C13: 1178 actual ($) | D13: 1178 at that mix ($) | E13: Campaign actual ($) | F13: Total gap ($) | G13: Gap explained by mix ($) | H13: % of gap explained
A14: 916 | B14: =H5 -> 0.18261973 | C14: =(E9+E10)/(F9+F10) -> 64.053107 | D14: =1/(B14/K9+(1-B14)/K10) -> 60.487794 | E14: =(E5+E6)/(F5+F6) -> 9.356875 | F14: =C14-E14 -> 54.696232 | G14: =C14-D14 -> 3.5653133 | H14: =IFERROR(G14/F14,0) -> 0.065183892
A15: 936 | B15: =H7 -> 0.047525895 | C15: =(E9+E10)/(F9+F10) -> 64.053107 | D15: =1/(B15/K9+(1-B15)/K10) -> 71.639002 | E15: =(E7+E8)/(F7+F8) -> 24.520085 | F15: =C15-E15 -> 39.533022 | G15: =C15-D15 -> -7.585895 | H15: =IFERROR(G15/F15,0) -> -0.19188755
A17: Method: 1178 cost per approved conversion for Men 30-34 and everyone else is held fixed; only the spend split between the two groups changes (cost = 1 / sum of share ÷ group cost).

Sheet Scenario Estimates
A1: Estimated impact of the recommendations (scenarios, not forecasts)
A2: Total budget is held constant. Blue cells are assumptions you can change. Optimistic = new dollars perform at the receiving segment's current CPA; conservative = they cost 1.5x that.
A4: Assumptions
A5: Efficiency multiplier, optimistic (new-dollar CPA = current CPA x this) | B5: 1
A6: Efficiency multiplier, conservative | B6: 1.5
A7: Share of zero-approved-ad spend redeployed | B7: 0.5
A8: Share of campaign 1178 spend moved to 936 (test) | B8: 0.05
A9: Target approval rate (AR), moderate | B9: 0.36
A10: Target approval rate (AR), strong | B10: 0.4
A12: Baseline (936-ad scope)
A13: Spend ($) | B13: =SUM(Data!$I$2:$I$937) -> 58705.23
A14: Approved conversions | B14: =SUM(Data!$K$2:$K$937) -> 1003
A15: Total conversions | B15: =SUM(Data!$J$2:$J$937) -> 3052
A16: Approval rate (AR) | B16: =B14/B15 -> 0.32863696
A17: Cost per approved conversion ($) | B17: =B13/B14 -> 58.529641
A20: Segment | B20: Age | C20: Gender | D20: Spend ($) | E20: Approved Conv. | F20: CPA ($)
A21: 30-34 F | B21: 30-34 | C21: F | D21: =SUMIFS(Data!$I$2:$I$937,Data!$D$2:$D$937,$B21,Data!$E$2:$E$937,$C21) -> 7611.48 | E21: =SUMIFS(Data!$K$2:$K$937,Data!$D$2:$D$937,$B21,Data!$E$2:$E$937,$C21) -> 180 | F21: =D21/E21 -> 42.286
A22: 30-34 M | B22: 30-34 | C22: M | D22: =SUMIFS(Data!$I$2:$I$937,Data!$D$2:$D$937,$B22,Data!$E$2:$E$937,$C22) -> 7640.92 | E22: =SUMIFS(Data!$K$2:$K$937,Data!$D$2:$D$937,$B22,Data!$E$2:$E$937,$C22) -> 263 | F22: =D22/E22 -> 29.052928
A23: 35-39 F | B23: 35-39 | C23: F | D23: =SUMIFS(Data!$I$2:$I$937,Data!$D$2:$D$937,$B23,Data!$E$2:$E$937,$C23) -> 6061.35 | E23: =SUMIFS(Data!$K$2:$K$937,Data!$D$2:$D$937,$B23,Data!$E$2:$E$937,$C23) -> 90 | F23: =D23/E23 -> 67.348333
A24: 35-39 M | B24: 35-39 | C24: M | D24: =SUMIFS(Data!$I$2:$I$937,Data!$D$2:$D$937,$B24,Data!$E$2:$E$937,$C24) -> 5051.08 | E24: =SUMIFS(Data!$K$2:$K$937,Data!$D$2:$D$937,$B24,Data!$E$2:$E$937,$C24) -> 109 | F24: =D24/E24 -> 46.340184
A25: 40-44 F | B25: 40-44 | C25: F | D25: =SUMIFS(Data!$I$2:$I$937,Data!$D$2:$D$937,$B25,Data!$E$2:$E$937,$C25) -> 7396.58 | E25: =SUMIFS(Data!$K$2:$K$937,Data!$D$2:$D$937,$B25,Data!$E$2:$E$937,$C25) -> 89 | F25: =D25/E25 -> 83.10764
A26: 40-44 M | B26: 40-44 | C26: M | D26: =SUMIFS(Data!$I$2:$I$937,Data!$D$2:$D$937,$B26,Data!$E$2:$E$937,$C26) -> 4193.15 | E26: =SUMIFS(Data!$K$2:$K$937,Data!$D$2:$D$937,$B26,Data!$E$2:$E$937,$C26) -> 73 | F26: =D26/E26 -> 57.440411
A27: 45-49 F | B27: 45-49 | C27: F | D27: =SUMIFS(Data!$I$2:$I$937,Data!$D$2:$D$937,$B27,Data!$E$2:$E$937,$C27) -> 13433.21 | E27: =SUMIFS(Data!$K$2:$K$937,Data!$D$2:$D$937,$B27,Data!$E$2:$E$937,$C27) -> 108 | F27: =D27/E27 -> 124.38157
A28: 45-49 M | B28: 45-49 | C28: M | D28: =SUMIFS(Data!$I$2:$I$937,Data!$D$2:$D$937,$B28,Data!$E$2:$E$937,$C28) -> 7317.46 | E28: =SUMIFS(Data!$K$2:$K$937,Data!$D$2:$D$937,$B28,Data!$E$2:$E$937,$C28) -> 91 | F28: =D28/E28 -> 80.411648
A30: A. Reallocate budget from low-efficiency segments to men and women 30-34 (split 50/50)
A31: Scenario | B31: Donor segments | C31: Share of donor budget moved | D31: Budget moved ($) | E31: Approved lost | F31: Approved gained (optimistic) | G31: New CPA, optimistic ($) | H31: CPA improvement, optimistic | I31: Approved gained (conservative) | J31: New CPA, conservative ($) | K31: CPA improvement, conservative | L31: Extra approved, optimistic | M31: Extra approved, conservative
A32: 1 | B32: Women 45-49 | C32: 0.25 | D32: =C32*(D27) -> 3358.3025 | E32: =C32*(E27) -> 27 | F32: =D32/2/(F22*$B$5)+D32/2/(F21*$B$5) -> 97.505673 | G32: =$B$13/($B$14-E32+F32) -> 54.685533 | H32: =1-G32/$B$17 -> 0.06567797 | I32: =D32/2/(F22*$B$6)+D32/2/(F21*$B$6) -> 65.003782 | J32: =$B$13/($B$14-E32+I32) -> 56.392907 | K32: =1-J32/$B$17 -> 0.036506863 | L32: =F32-E32 -> 70.505673 | M32: =I32-E32 -> 38.003782
A33: 2 | B33: Women 45-49 | C33: 0.5 | D33: =C33*(D27) -> 6716.605 | E33: =C33*(E27) -> 54 | F33: =D33/2/(F22*$B$5)+D33/2/(F21*$B$5) -> 195.01135 | G33: =$B$13/($B$14-E33+F33) -> 51.315251 | H33: =1-G33/$B$17 -> 0.12326044 | I33: =D33/2/(F22*$B$6)+D33/2/(F21*$B$6) -> 130.00756 | J33: =$B$13/($B$14-E33+I33) -> 54.40669 | K33: =1-J33/$B$17 -> 0.070442105 | L33: =F33-E33 -> 141.01135 | M33: =I33-E33 -> 76.007564
A34: 3 | B34: Women 45-49 + Women 40-44 + Men 45-49 | C34: 0.5 | D34: =C34*(D27+D25+D28) -> 14073.625 | E34: =C34*(E27+E25+E28) -> 144 | F34: =D34/2/(F22*$B$5)+D34/2/(F21*$B$5) -> 408.61664 | G34: =$B$13/($B$14-E34+F34) -> 46.311502 | H34: =1-G34/$B$17 -> 0.20875131 | I34: =D34/2/(F22*$B$6)+D34/2/(F21*$B$6) -> 272.41109 | J34: =$B$13/($B$14-E34+I34) -> 51.886737 | K34: =1-J34/$B$17 -> 0.11349641 | L34: =F34-E34 -> 264.61664 | M34: =I34-E34 -> 128.41109
A37: B. Raise the approval rate (total conversions unchanged)
A38: Scenario | B38: Target AR | C38: New approved | D38: New CPA ($) | E38: CPA improvement | F38: Extra approved
A39: ="AR to "&TEXT(B9,"0%") -> AR to 36% | B39: =B9 -> 0.36 | C39: =$B$15*B39 -> 1098.72 | D39: =$B$13/C39 -> 53.430565 | E39: =1-D39/$B$17 -> 0.087119557 | F39: =C39-$B$14 -> 95.72
A40: ="AR to "&TEXT(B10,"0%") -> AR to 40% | B40: =B10 -> 0.4 | C40: =$B$15*B40 -> 1220.8 | D40: =$B$13/C40 -> 48.087508 | E40: =1-D40/$B$17 -> 0.1784076 | F40: =C40-$B$14 -> 217.8
A41: Women's AR lifted to men's AR level | B41: =SUMIFS(Data!$K$2:$K$937,Data!$E$2:$E$937,"M")/SUMIFS(Data!$J$2:$J$937,Data!$E$2:$E$937,"M") -> 0.35852843 | C41: =SUMIFS(Data!$K$2:$K$937,Data!$E$2:$E$937,"M")+SUMIFS(Data!$J$2:$J$937,Data!$E$2:$E$937,"F")*B41 -> 1094.2288 | D41: =$B$13/C41 -> 53.649869 | E41: =1-D41/$B$17 -> 0.08337266 | F41: =C41-$B$14 -> 91.228763
A43: C. Pause part of the zero-approved ads and redeploy the budget at the blended CPA
A44: Scenario | B44: Zero-approved spend ($) | C44: Share redeployed | D44: New approved, optimistic | E44: New CPA, optimistic ($) | F44: CPA improvement, optimistic | G44: New approved, conservative | H44: New CPA, conservative ($) | I44: CPA improvement, conservative
A45: Redeploy waste | B45: =SUMIFS(Data!$I$2:$I$937,Data!$K$2:$K$937,0) -> 14754.42 | C45: =$B$7 -> 0.5 | D45: =$B$14+B45*C45/($B$17*$B$5) -> 1129.0423 | E45: =$B$13/D45 -> 51.995599 | F45: =1-E45/$B$17 -> 0.11163647 | G45: =$B$14+B45*C45/($B$17*$B$6) -> 1087.0282 | H45: =$B$13/G45 -> 54.005251 | I45: =1-H45/$B$17 -> 0.077300841
A47: D. Test: move budget from campaign 1178 to campaign 936
A48: Scenario | B48: Budget moved ($) | C48: 1178 CPA ($) | D48: 936 CPA ($) | E48: New approved, optimistic | F48: New CPA, optimistic ($) | G48: CPA improvement, optimistic | H48: New approved, conservative | I48: New CPA, conservative ($) | J48: CPA improvement, conservative
A49: 1178 to 936 | B49: =$B$8*SUMIFS(Data!$I$2:$I$937,Data!$B$2:$B$937,1178) -> 2783.1075 | C49: =SUMIFS(Data!$I$2:$I$937,Data!$B$2:$B$937,1178)/SUMIFS(Data!$K$2:$K$937,Data!$B$2:$B$937,1178) -> 64.053107 | D49: =SUMIFS(Data!$I$2:$I$937,Data!$B$2:$B$937,936)/SUMIFS(Data!$K$2:$K$937,Data!$B$2:$B$937,936) -> 24.520085 | E49: =$B$14-B49/C49+B49/(D49*$B$5) -> 1073.0532 | F49: =$B$13/E49 -> 54.708593 | G49: =1-F49/$B$17 -> 0.065283974 | H49: =$B$14-B49/C49+B49/(D49*$B$6) -> 1035.2188 | I49: =$B$13/H49 -> 56.708042 | J49: =1-I49/$B$17 -> 0.031122681
...

Sheet Data
A1: ad_id | B1: xyz_campaign_id | C1: fb_campaign_id | D1: age | E1: gender | F1: interest | G1: Impressions | H1: Clicks | I1: Spent | J1: Total_Conversion | K1: Approved_Conversion | M1: Source: KAG_conversion_data.csv, rows with Clicks > 0 (936 of 1,143 ads).
A2: 708746 | B2: 916 | C2: 103916 | D2: 30-34 | E2: M | F2: 15 | G2: 7350 | H2: 1 | I2: 1.4299999 | J2: 2 | K2: 1
A3: 708749 | B3: 916 | C3: 103917 | D3: 30-34 | E3: M | F3: 16 | G3: 17861 | H3: 2 | I3: 1.82 | J3: 2 | K3: 0
A4: 708815 | B4: 916 | C4: 103928 | D4: 30-34 | E4: M | F4: 28 | G4: 4259 | H4: 1 | I4: 1.25 | J4: 1 | K4: 0
